0
1
raised ValueError()
ret was: None
#<<<<<<< HEAD
raised OSError()
raised ValueError('generator already executing',)
raised ValueError('generator already executing',)
0
ignore CancelledError
1
raised CancelledError()
None
CancelledError()
CancelledError()
1
#=======
#ValueError from just-started gen
#>>>>>>> tests/generator_pend_throw: It's now allowed to pend_throw() just started gen.
